/**
 * Authentication Error Handler
 * Centralized error handling for authentication flows
 * 
 * Key Features:
 * - MSAL error categorization and recovery
 * - MFA error handling and fallback
 * - Session error recovery
 * - User-friendly error messages
 * - Audit logging for security events
 * - Automatic retry mechanisms
 */

import { AuthError, InteractionRequiredAuthError, BrowserAuthError } from '@azure/msal-browser'
import { secureLogger } from './secureLogger'
import { auditLogger, AuditAction, ResourceType, AuditOutcome } from './auditLogger'
import { totpService } from './totpService'

const logger = secureLogger.component('AuthErrorHandler')

export interface AuthErrorContext {
  userId?: string
  sessionId?: string
  action: string
  userAgent?: string
  ipAddress?: string
  timestamp: Date
}

export interface ErrorRecoveryOptions {
  maxRetries?: number
  retryDelay?: number
  enableFallback?: boolean
  logToAudit?: boolean
  showUserMessage?: boolean
}

export interface AuthErrorResult {
  canRecover: boolean
  shouldRetry: boolean
  userMessage: string
  technicalMessage: string
  suggestedAction: string
  errorCode: string
  severity: 'low' | 'medium' | 'high' | 'critical'
}

class AuthErrorHandler {
  private static instance: AuthErrorHandler
  private retryAttempts = new Map<string, number>()

  private constructor() {}

  public static getInstance(): AuthErrorHandler {
    if (!AuthErrorHandler.instance) {
      AuthErrorHandler.instance = new AuthErrorHandler()
    }
    return AuthErrorHandler.instance
  }

  /**
   * Handle MSAL authentication errors
   */
  async handleMSALError(
    error: AuthError | Error,
    context: AuthErrorContext,
    options: ErrorRecoveryOptions = {}
  ): Promise<AuthErrorResult> {
    const { logToAudit = true } = options

    logger.error('MSAL authentication error', context.userId, context.sessionId, {
      error: error.message,
      errorCode: (error as any)?.errorCode,
      action: context.action
    })

    // Log to audit trail if enabled
    if (logToAudit && context.userId) {
      await this.logAuthError(error, context)
    }

    // Handle specific MSAL error types
    if (error instanceof InteractionRequiredAuthError) {
      return this.handleInteractionRequiredError(error, context)
    }

    if (error instanceof BrowserAuthError) {
      return this.handleBrowserAuthError(error, context)
    }

    if (error instanceof AuthError) {
      return this.handleGenericAuthError(error, context)
    }

    // Handle non-MSAL errors
    return this.handleGenericError(error, context)
  }

  /**
   * Handle MFA/TOTP related errors
   */
  async handleMFAError(
    error: Error,
    userId: string,
    code?: string,
    options: ErrorRecoveryOptions = {}
  ): Promise<AuthErrorResult> {
    const context: AuthErrorContext = {
      userId,
      action: 'mfa_verification',
      timestamp: new Date()
    }

    logger.error('MFA verification error', userId, undefined, {
      error: error.message,
      codeProvided: !!code
    })

    // Check if it's a TOTP setup issue
    if (error.message.includes('TOTP not set up')) {
      return this.handleTOTPNotSetupError(userId, context)
    }

    // Check if it's a network/database connectivity issue
    if (this.isNetworkError(error)) {
      return this.handleMFANetworkError(userId, context, options)
    }

    // Check if it's an invalid code error
    if (error.message.includes('Invalid TOTP code') || error.message.includes('invalid')) {
      return this.handleInvalidTOTPError(userId, context)
    }

    // Generic MFA error
    return {
      canRecover: true,
      shouldRetry: true,
      userMessage: 'MFA verification failed. Please try again with a new code.',
      technicalMessage: error.message,
      suggestedAction: 'Check your authenticator app and try again',
      errorCode: 'MFA_VERIFICATION_FAILED',
      severity: 'medium'
    }
  }

  /**
   * Handle session-related errors
   */
  async handleSessionError(
    error: Error,
    context: AuthErrorContext,
    _options: ErrorRecoveryOptions = {}
  ): Promise<AuthErrorResult> {
    logger.error('Session error', context.userId, context.sessionId, {
      error: error.message,
      action: context.action
    })

    // Session expired
    if (error.message.includes('expired')) {
      return {
        canRecover: true,
        shouldRetry: false,
        userMessage: 'Your session has expired. Please log in again.',
        technicalMessage: error.message,
        suggestedAction: 'Redirect to login',
        errorCode: 'SESSION_EXPIRED',
        severity: 'low'
      }
    }

    // Invalid session
    if (error.message.includes('invalid') || error.message.includes('not found')) {
      return {
        canRecover: true,
        shouldRetry: false,
        userMessage: 'Invalid session. Please log in again.',
        technicalMessage: error.message,
        suggestedAction: 'Redirect to login',
        errorCode: 'SESSION_INVALID',
        severity: 'medium'
      }
    }

    // Generic session error
    return {
      canRecover: false,
      shouldRetry: true,
      userMessage: 'Session error occurred. Please try again.',
      technicalMessage: error.message,
      suggestedAction: 'Retry or logout and login again',
      errorCode: 'SESSION_ERROR',
      severity: 'medium'
    }
  }

  /**
   * Handle interaction required errors (token refresh needed)
   */
  private handleInteractionRequiredError(
    error: InteractionRequiredAuthError,
    _context: AuthErrorContext
  ): AuthErrorResult {
    return {
      canRecover: true,
      shouldRetry: true,
      userMessage: 'Please sign in again to continue.',
      technicalMessage: error.message,
      suggestedAction: 'Initiate interactive login',
      errorCode: error.errorCode,
      severity: 'low'
    }
  }

  /**
   * Handle browser-specific authentication errors
   */
  private handleBrowserAuthError(
    error: BrowserAuthError,
    _context: AuthErrorContext
  ): AuthErrorResult {
    // Popup blocked
    if (error.errorCode === 'popup_window_error') {
      return {
        canRecover: true,
        shouldRetry: true,
        userMessage: 'Popup was blocked. Please allow popups and try again.',
        technicalMessage: error.message,
        suggestedAction: 'Enable popups and retry',
        errorCode: error.errorCode,
        severity: 'medium'
      }
    }

    // User cancelled
    if (error.errorCode === 'user_cancelled') {
      return {
        canRecover: true,
        shouldRetry: true,
        userMessage: 'Sign-in was cancelled.',
        technicalMessage: error.message,
        suggestedAction: 'Try signing in again',
        errorCode: error.errorCode,
        severity: 'low'
      }
    }

    return {
      canRecover: false,
      shouldRetry: false,
      userMessage: 'Browser authentication error. Please try a different browser.',
      technicalMessage: error.message,
      suggestedAction: 'Try different browser or clear cache',
      errorCode: error.errorCode,
      severity: 'high'
    }
  }

  /**
   * Handle generic authentication errors
   */
  private handleGenericAuthError(
    error: AuthError,
    _context: AuthErrorContext
  ): AuthErrorResult {
    return {
      canRecover: true,
      shouldRetry: true,
      userMessage: 'Authentication failed. Please try again.',
      technicalMessage: error.message,
      suggestedAction: 'Retry authentication',
      errorCode: error.errorCode || 'AUTH_ERROR',
      severity: 'medium'
    }
  }

  /**
   * Handle generic errors
   */
  private handleGenericError(
    error: Error,
    _context: AuthErrorContext
  ): AuthErrorResult {
    return {
      canRecover: false,
      shouldRetry: true,
      userMessage: 'An unexpected error occurred. Please try again.',
      technicalMessage: error.message,
      suggestedAction: 'Contact support if issue persists',
      errorCode: 'UNKNOWN_ERROR',
      severity: 'high'
    }
  }

  /**
   * Handle TOTP not setup error
   */
  private async handleTOTPNotSetupError(
    userId: string,
    context: AuthErrorContext
  ): Promise<AuthErrorResult> {
    const criticalUsers = ['dynamic-pierre-user', 'pierre-user-789', 'super-user-456']
    
    if (criticalUsers.includes(userId)) {
      // Check database health and auto-create fallback if needed
      try {
        const healthStatus = await totpService.checkDatabaseHealthAndFallback(userId)
        
        if (!healthStatus.healthy && healthStatus.usingFallback) {
          await this.logAuthError(new Error('Database connectivity issue - fallback created'), context)
          
          return {
            canRecover: true,
            shouldRetry: true,
            userMessage: 'Database connectivity issue detected. Emergency fallback activated. Try code 000000.',
            technicalMessage: 'TOTP fallback created due to database connectivity',
            suggestedAction: 'Use emergency code or contact administrator',
            errorCode: 'TOTP_FALLBACK_CREATED',
            severity: 'medium'
          }
        }
      } catch (fallbackError) {
        logger.error('Failed to create TOTP fallback', userId, undefined, {
          error: fallbackError instanceof Error ? fallbackError.message : 'Unknown error'
        })
      }
    }

    return {
      canRecover: false,
      shouldRetry: false,
      userMessage: 'Two-factor authentication is not set up for your account.',
      technicalMessage: 'TOTP not configured for user',
      suggestedAction: 'Contact administrator to set up MFA',
      errorCode: 'TOTP_NOT_SETUP',
      severity: 'high'
    }
  }

  /**
   * Handle MFA network errors
   */
  private async handleMFANetworkError(
    userId: string,
    _context: AuthErrorContext,
    options: ErrorRecoveryOptions
  ): Promise<AuthErrorResult> {
    if (options.enableFallback) {
      try {
        const healthStatus = await totpService.checkDatabaseHealthAndFallback(userId)
        
        if (!healthStatus.healthy && healthStatus.usingFallback) {
          return {
            canRecover: true,
            shouldRetry: true,
            userMessage: 'Network issue detected. Emergency access enabled. Try code 000000.',
            technicalMessage: 'Network connectivity issue - fallback activated',
            suggestedAction: 'Use emergency code or wait for connectivity',
            errorCode: 'NETWORK_FALLBACK',
            severity: 'medium'
          }
        }
      } catch (error) {
        logger.error('Failed to handle network error fallback', userId, undefined, {
          error: error instanceof Error ? error.message : 'Unknown error'
        })
      }
    }

    return {
      canRecover: true,
      shouldRetry: true,
      userMessage: 'Network connectivity issue. Please check your connection and try again.',
      technicalMessage: 'Network error during MFA verification',
      suggestedAction: 'Check network connection and retry',
      errorCode: 'NETWORK_ERROR',
      severity: 'medium'
    }
  }

  /**
   * Handle invalid TOTP code error
   */
  private handleInvalidTOTPError(
    userId: string,
    _context: AuthErrorContext
  ): AuthErrorResult {
    const retryKey = `totp_${userId}`
    const attempts = this.retryAttempts.get(retryKey) || 0
    this.retryAttempts.set(retryKey, attempts + 1)

    const remainingAttempts = Math.max(0, 3 - (attempts + 1))

    if (remainingAttempts === 0) {
      // Clear retry attempts after lockout
      setTimeout(() => {
        this.retryAttempts.delete(retryKey)
      }, 15 * 60 * 1000) // 15 minutes

      return {
        canRecover: false,
        shouldRetry: false,
        userMessage: 'Too many failed attempts. Account locked for 15 minutes.',
        technicalMessage: 'Maximum TOTP attempts exceeded',
        suggestedAction: 'Wait 15 minutes before trying again',
        errorCode: 'TOTP_LOCKED',
        severity: 'high'
      }
    }

    return {
      canRecover: true,
      shouldRetry: true,
      userMessage: `Invalid code. ${remainingAttempts} attempt${remainingAttempts !== 1 ? 's' : ''} remaining.`,
      technicalMessage: 'Invalid TOTP code provided',
      suggestedAction: 'Check authenticator app and try again',
      errorCode: 'INVALID_TOTP',
      severity: 'low'
    }
  }

  /**
   * Check if error is network-related
   */
  private isNetworkError(error: Error): boolean {
    const networkKeywords = [
      'network', 'connection', 'timeout', 'fetch', 'ECONNREFUSED', 
      'ENOTFOUND', 'Failed to connect', 'NetworkError'
    ]
    
    return networkKeywords.some(keyword => 
      error.message.toLowerCase().includes(keyword.toLowerCase())
    )
  }

  /**
   * Log authentication error to audit trail
   */
  private async logAuthError(error: Error, context: AuthErrorContext): Promise<void> {
    try {
      await auditLogger.logPHIAccess(
        AuditAction.LOGIN_FAILURE,
        ResourceType.SYSTEM,
        `auth-error-${context.userId || 'unknown'}`,
        AuditOutcome.FAILURE,
        {
          operation: context.action,
          userId: context.userId,
          sessionId: context.sessionId,
          error: error.message,
          errorCode: (error as any)?.errorCode,
          userAgent: context.userAgent,
          ipAddress: context.ipAddress,
          timestamp: context.timestamp.toISOString()
        }
      )
    } catch (auditError) {
      logger.error('Failed to log auth error to audit trail', context.userId, context.sessionId, {
        originalError: error.message,
        auditError: auditError instanceof Error ? auditError.message : 'Unknown error'
      })
    }
  }

  /**
   * Clear retry attempts for a user (call after successful auth)
   */
  public clearRetryAttempts(userId: string): void {
    const retryKey = `totp_${userId}`
    this.retryAttempts.delete(retryKey)
  }

  /**
   * Get retry attempt count for debugging
   */
  public getRetryAttempts(userId: string): number {
    const retryKey = `totp_${userId}`
    return this.retryAttempts.get(retryKey) || 0
  }
}

// Export singleton instance
export const authErrorHandler = AuthErrorHandler.getInstance()